Workbook

Sheet 2016-17
A1: शालेय पोषण आहार योजना (सन 2017-18)
A2: पंचायत समिती मुरबाड. जि. ठाणे
A3: तांदूळ व धान्यादी मालाचे उपयोगिता प्रमाणपत्र (माहे एप्रिल 2017 ते मार्च 2018)
A4: जि. प. प्राथमिक शाळा देवराळवाडी | J4: केंद्र : देवगांव | AJ4: इ. 1 ते 5
A5: महिना व वर्ष | C5: एप्रिल 17 | F5: जून 17 | I5: जुलै 17 | L5: ऑगस्ट 17 | O5: सप्टेंबर 17 | R5: ऑक्टोंबर 17 | U5: नोव्हेंबर 17 | X5: डिसेंबर 17 | AA5: जानेवारी 18 | AD5: फेब्रुवारी 18 | AG5: मार्च 18 | AJ5: एकूण
A6: पटसंख्या | C6: =C8*30 -> 330 | F6: =F8*31 -> 403 | I6: 786 | L6: =L8*32 -> 576 | O6: =O8*32 -> 672 | R6: =R8*32 -> 352 | U6: =U8*32 -> 672 | X6: =X8*32 -> 640 | AA6: =AA8*32 -> 800 | AD6: =AD8*32 -> 0 | AG6: =AG8*32 -> 0 | AJ6: =SUM(C6:AI6) -> 5231
A7: ताटांची संख्या | C7: =C6 -> 330 | F7: =F6 -> 403 | I7: =I6 -> 786 | L7: =L6 -> 576 | O7: =O6 -> 672 | R7: =R6 -> 352 | U7: =U6 -> 672 | X7: =X6 -> 640 | AA7: =AA6 -> 800 | AD7: =AD6 -> 0 | AG7: =AG6 -> 0 | AJ7: =AJ6 -> 5231
A8: कामाचे दिवस | C8: 11 | F8: 13 | I8: 25 | L8: 18 | O8: 21 | R8: 11 | U8: 21 | X8: 20 | AA8: 25 | AJ8: =SUM(C8:AI8) -> 165
A9: वस्तूचे नांव | B9: मागील शिल्लक मार्च 2017 | C9: प्राप्त | D9: शिजविलेला | E9: शिल्लक | F9: प्राप्त | G9: शिजविलेला | H9: शिल्लक | I9: प्राप्त | J9: शिजविलेला | K9: शिल्लक | L9: प्राप्त | M9: शिजविलेला | N9: शिल्लक | O9: प्राप्त | P9: शिजविलेला | Q9: शिल्लक | R9: प्राप्त | S9: शिजविलेला | T9: शिल्लक | U9: प्राप्त | V9: शिजविलेला | W9: शिल्लक | X9: प्राप्त | Y9: शिजविलेला | Z9: शिल्लक | AA9: प्राप्त | AB9: शिजविलेला | AC9: शिल्लक | AD9: प्राप्त | AE9: शिजविलेला | AF9: शिल्लक | AG9: प्राप्त | AH9: शिजविलेला | AI9: शिल्लक | AJ9: प्राप्त | AK9: शिजविलेला | AL9: शिल्लक
A10: तांदूळ | B10: -35.1 | C10: 0 | D10: =C7*0.1 -> 33 | E10: =B10+C10-D10 -> -68.1 | F10: 0 | G10: =F7*0.1 -> 40.3 | H10: =E10+F10-G10 -> -108.4 | I10: 150 | J10: =I7*0.1 -> 78.6 | K10: =H10+I10-J10 -> -37 | L10: 0 | M10: =L7*0.1 -> 57.6 | N10: =K10+L10-M10 -> -94.6 | O10: 150 | P10: =O7*0.1 -> 67.2 | Q10: =N10+O10-P10 -> -11.8 | R10: 0 | S10: =R7*0.1 -> 35.2 | T10: =Q10+R10-S10 -> -47 | U10: 100 | V10: =U7*0.1 -> 67.2 | W10: =T10+U10-V10 -> -14.2 | X10: 147 | Y10: 64 | Z10: =W10+X10-Y10 -> 68.8 | AA10: 0 | AB10: =AA7*0.1 -> 80 | AC10: =Z10+AA10-AB10 -> -11.2 | AD10: 0 | AE10: =AD7*0.1 -> 0 | AF10: =AC10+AD10-AE10 -> -11.2 | AG10: 0 | AH10: =AG7*0.1 -> 0 | AI10: =AF10+AG10-AH10 -> -11.2 | AJ10: =SUM(AG10,AD10,AA10,X10,U10,R10,O10,L10,I10,F10,C10) -> 547 | AK10: =SUM(AH10,AE10,AB10,Y10,V10,S10,P10,M10,J10,G10,D10) -> 523.1 | AL10: =B10+AJ10-AK10 -> -11.2
A11: मुगडाळ | B11: -7.86 | C11: 0 | D11: 3 | E11: =B11+C11-D11 -> -10.86 | F11: 0 | G11: 1.86 | H11: =E11+F11-G11 -> -12.72 | I11: 10 | J11: 5.66 | K11: =H11+I11-J11 -> -8.38 | L11: 3.2 | M11: 3.2 | N11: =K11+L11-M11 -> -8.38 | O11: 4.48 | P11: 4.48 | Q11: =N11+O11-P11 -> -8.38 | R11: 1.92 | S11: 1.92 | T11: =Q11+R11-S11 -> -8.38 | U11: 4.48 | V11: 4.48 | W11: =T11+U11-V11 -> -8.38 | X11: 6 | Y11: 4.48 | Z11: =W11+X11-Y11 -> -6.86 | AA11: 0 | AB11: 5.12 | AC11: =Z11+AA11-AB11 -> -11.98 | AD11: 0 | AE11: 0 | AF11: =AC11+AD11-AE11 -> -11.98 | AG11: 0 | AH11: 0 | AI11: =AF11+AG11-AH11 -> -11.98 | AJ11: =SUM(AG11,AD11,AA11,X11,U11,R11,O11,L11,I11,F11,C11) -> 30.08 | AK11: =SUM(AH11,AE11,AB11,Y11,V11,S11,P11,M11,J11,G11,D11) -> 34.2 | AL11: =B11+AJ11-AK11 -> -11.98
A12: तुरडाळ | B12: -16.38 | C12: 0 | D12: 1.2 | E12: =B12+C12-D12 -> -17.58 | F12: 0 | G12: 3.1 | H12: =E12+F12-G12 -> -20.68 | I12: 10 | J12: 4.4 | K12: =H12+I12-J12 -> -15.08 | L12: 3.84 | M12: 3.84 | N12: =K12+L12-M12 -> -15.08 | O12: 4.48 | P12: 4.48 | Q12: =N12+O12-P12 -> -15.08 | R12: 2.56 | S12: 2.56 | T12: =Q12+R12-S12 -> -15.08 | U12: 4.48 | V12: 4.48 | W12: =T12+U12-V12 -> -15.08 | X12: 0 | Y12: 2.56 | Z12: =W12+X12-Y12 -> -17.64 | AA12: 10 | AB12: 0 | AC12: =Z12+AA12-AB12 -> -7.64 | AD12: 0 | AE12: 0 | AF12: =AC12+AD12-AE12 -> -7.64 | AG12: 0 | AH12: 0 | AI12: =AF12+AG12-AH12 -> -7.64 | AJ12: =SUM(AG12,AD12,AA12,X12,U12,R12,O12,L12,I12,F12,C12) -> 35.36 | AK12: =SUM(AH12,AE12,AB12,Y12,V12,S12,P12,M12,J12,G12,D12) -> 26.62 | AL12: =B12+AJ12-AK12 -> -7.64
A13: मसूरडाळ | B13: 0 | C13: 0 | D13: 0 | E13: =B13+C13-D13 -> 0 | F13: 0 | G13: 0 | H13: =E13+F13-G13 -> 0 | I13: 0 | J13: 0 | K13: =H13+I13-J13 -> 0 | L13: 0 | M13: 0 | N13: =K13+L13-M13 -> 0 | O13: 0 | P13: 0 | Q13: =N13+O13-P13 -> 0 | R13: 0 | S13: 0 | T13: =Q13+R13-S13 -> 0 | U13: 0 | V13: 0 | W13: =T13+U13-V13 -> 0 | X13: 0 | Y13: 0 | Z13: =W13+X13-Y13 -> 0 | AA13: 0 | AB13: 0 | AC13: =Z13+AA13-AB13 -> 0 | AD13: 0 | AE13: 0 | AF13: =AC13+AD13-AE13 -> 0 | AG13: 0 | AH13: 0 | AI13: =AF13+AG13-AH13 -> 0 | AJ13: =SUM(AG13,AD13,AA13,X13,U13,R13,O13,L13,I13,F13,C13) -> 0 | AK13: =SUM(AH13,AE13,AB13,Y13,V13,S13,P13,M13,J13,G13,D13) -> 0 | AL13: =B13+AJ13-AK13 -> 0
A14: मटकी | B14: 0 | C14: 0 | D14: 0 | E14: =B14+C14-D14 -> 0 | F14: 0 | G14: 0 | H14: =E14+F14-G14 -> 0 | I14: 0 | J14: 0 | K14: =H14+I14-J14 -> 0 | L14: 0 | M14: 0 | N14: =K14+L14-M14 -> 0 | O14: 0 | P14: 0 | Q14: =N14+O14-P14 -> 0 | R14: 0 | S14: 0 | T14: =Q14+R14-S14 -> 0 | U14: 0 | V14: 0 | W14: =T14+U14-V14 -> 0 | X14: 6 | Y14: 1.28 | Z14: =W14+X14-Y14 -> 4.72 | AA14: 0 | AB14: 5.76 | AC14: =Z14+AA14-AB14 -> -1.04 | AD14: 0 | AE14: 0 | AF14: =AC14+AD14-AE14 -> -1.04 | AG14: 0 | AH14: 0 | AI14: =AF14+AG14-AH14 -> -1.04 | AJ14: =SUM(AG14,AD14,AA14,X14,U14,R14,O14,L14,I14,F14,C14) -> 6 | AK14: =SUM(AH14,AE14,AB14,Y14,V14,S14,P14,M14,J14,G14,D14) -> 7.04 | AL14: =B14+AJ14-AK14 -> -1.04
A15: हरभरा | B15: 0 | C15: 0 | D15: 0 | E15: =B15+C15-D15 -> 0 | F15: 0 | G15: 0 | H15: =E15+F15-G15 -> 0 | I15: 0 | J15: 0 | K15: =H15+I15-J15 -> 0 | L15: 0 | M15: 0 | N15: =K15+L15-M15 -> 0 | O15: 0 | P15: 0 | Q15: =N15+O15-P15 -> 0 | R15: 0 | S15: 0 | T15: =Q15+R15-S15 -> 0 | U15: 0 | V15: 0 | W15: =T15+U15-V15 -> 0 | X15: 0 | Y15: 0 | Z15: =W15+X15-Y15 -> 0 | AA15: 0 | AB15: 0 | AC15: =Z15+AA15-AB15 -> 0 | AD15: 0 | AE15: 0 | AF15: =AC15+AD15-AE15 -> 0 | AG15: 0 | AH15: 0 | AI15: =AF15+AG15-AH15 -> 0 | AJ15: =SUM(AG15,AD15,AA15,X15,U15,R15,O15,L15,I15,F15,C15) -> 0 | AK15: =SUM(AH15,AE15,AB15,Y15,V15,S15,P15,M15,J15,G15,D15) -> 0 | AL15: =B15+AJ15-AK15 -> 0
A16: वाटाणा | B16: -0.882 | C16: 0 | D16: 2.4 | E16: =B16+C16-D16 -> -3.282 | F16: 0 | G16: 3.1 | H16: =E16+F16-G16 -> -6.382 | I16: 11 | J16: 5.66 | K16: =H16+I16-J16 -> -1.042 | L16: 4.48 | M16: 4.48 | N16: =K16+L16-M16 -> -1.042 | O16: 4.48 | P16: 4.48 | Q16: =N16+O16-P16 -> -1.042 | R16: 2.56 | S16: 2.56 | T16: =Q16+R16-S16 -> -1.042 | U16: 4.48 | V16: 4.48 | W16: =T16+U16-V16 -> -1.042 | X16: 6 | Y16: 4.48 | Z16: =W16+X16-Y16 -> 0.478 | AA16: 0 | AB16: 5.12 | AC16: =Z16+AA16-AB16 -> -4.642 | AD16: 0 | AE16: 0 | AF16: =AC16+AD16-AE16 -> -4.642 | AG16: 0 | AH16: 0 | AI16: =AF16+AG16-AH16 -> -4.642 | AJ16: =SUM(AG16,AD16,AA16,X16,U16,R16,O16,L16,I16,F16,C16) -> 33 | AK16: =SUM(AH16,AE16,AB16,Y16,V16,S16,P16,M16,J16,G16,D16) -> 36.76 | AL16: =B16+AJ16-AK16 -> -4.642
A17: जिरे | B17: -4.782 | C17: 0 | D17: =ROUND(C7*15,0)/10000 -> 0.495 | E17: =B17+C17-D17 -> -5.277 | F17: 0 | G17: =ROUND(F7*15,0)/10000 -> 0.6045 | H17: =E17+F17-G17 -> -5.8815 | I17: 0.5 | J17: =ROUND(I7*15,0)/10000 -> 1.179 | K17: =H17+I17-J17 -> -6.5605 | L17: 0.864 | M17: =ROUND(L7*15,0)/10000 -> 0.864 | N17: =K17+L17-M17 -> -6.5605 | O17: 1.008 | P17: =ROUND(O7*15,0)/10000 -> 1.008 | Q17: =N17+O17-P17 -> -6.5605 | R17: 0.528 | S17: =ROUND(R7*15,0)/10000 -> 0.528 | T17: =Q17+R17-S17 -> -6.5605 | U17: 1.008 | V17: =ROUND(U7*15,0)/10000 -> 1.008 | W17: =T17+U17-V17 -> -6.5605 | X17: 0.5 | Y17: 0.96 | Z17: =W17+X17-Y17 -> -7.0205 | AA17: 0 | AB17: =ROUND(AA7*15,0)/10000 -> 1.2 | AC17: =Z17+AA17-AB17 -> -8.2205 | AD17: 0 | AE17: =ROUND(AD7*15,0)/10000 -> 0 | AF17: =AC17+AD17-AE17 -> -8.2205 | AG17: 0 | AH17: =ROUND(AG7*15,0)/10000 -> 0 | AI17: =AF17+AG17-AH17 -> -8.2205 | AJ17: =SUM(AG17,AD17,AA17,X17,U17,R17,O17,L17,I17,F17,C17) -> 4.408 | AK17: =SUM(AH17,AE17,AB17,Y17,V17,S17,P17,M17,J17,G17,D17) -> 7.8465 | AL17: =B17+AJ17-AK17 -> -8.2205
A18: मोहरी | B18: -4.782 | C18: 0 | D18: =ROUND(C7*15,0)/10000 -> 0.495 | E18: =B18+C18-D18 -> -5.277 | F18: 0 | G18: =ROUND(F7*15,0)/10000 -> 0.6045 | H18: =E18+F18-G18 -> -5.8815 | I18: 0.5 | J18: =ROUND(I7*15,0)/10000 -> 1.179 | K18: =H18+I18-J18 -> -6.5605 | L18: 0.864 | M18: =ROUND(L7*15,0)/10000 -> 0.864 | N18: =K18+L18-M18 -> -6.5605 | O18: 1.008 | P18: =ROUND(O7*15,0)/10000 -> 1.008 | Q18: =N18+O18-P18 -> -6.5605 | R18: 0.528 | S18: =ROUND(R7*15,0)/10000 -> 0.528 | T18: =Q18+R18-S18 -> -6.5605 | U18: 1.008 | V18: =ROUND(U7*15,0)/10000 -> 1.008 | W18: =T18+U18-V18 -> -6.5605 | X18: 0.5 | Y18: 0.96 | Z18: =W18+X18-Y18 -> -7.0205 | AA18: 0 | AB18: =ROUND(AA7*15,0)/10000 -> 1.2 | AC18: =Z18+AA18-AB18 -> -8.2205 | AD18: 0 | AE18: =ROUND(AD7*15,0)/10000 -> 0 | AF18: =AC18+AD18-AE18 -> -8.2205 | AG18: 0 | AH18: =ROUND(AG7*15,0)/10000 -> 0 | AI18: =AF18+AG18-AH18 -> -8.2205 | AJ18: =SUM(AG18,AD18,AA18,X18,U18,R18,O18,L18,I18,F18,C18) -> 4.408 | AK18: =SUM(AH18,AE18,AB18,Y18,V18,S18,P18,M18,J18,G18,D18) -> 7.8465 | AL18: =B18+AJ18-AK18 -> -8.2205
A19: हळद | B19: -4.176 | C19: 0 | D19: =ROUND(C7*15,0)/10000 -> 0.495 | E19: =B19+C19-D19 -> -4.671 | F19: 0 | G19: =ROUND(F7*15,0)/10000 -> 0.6045 | H19: =E19+F19-G19 -> -5.2755 | I19: 0.5 | J19: =ROUND(I7*15,0)/10000 -> 1.179 | K19: =H19+I19-J19 -> -5.9545 | L19: 0.864 | M19: =ROUND(L7*15,0)/10000 -> 0.864 | N19: =K19+L19-M19 -> -5.9545 | O19: 1.008 | P19: =ROUND(O7*15,0)/10000 -> 1.008 | Q19: =N19+O19-P19 -> -5.9545 | R19: 0.528 | S19: =ROUND(R7*15,0)/10000 -> 0.528 | T19: =Q19+R19-S19 -> -5.9545 | U19: 1.008 | V19: =ROUND(U7*15,0)/10000 -> 1.008 | W19: =T19+U19-V19 -> -5.9545 | X19: 0.5 | Y19: 0.96 | Z19: =W19+X19-Y19 -> -6.4145 | AA19: 0 | AB19: =ROUND(AA7*15,0)/10000 -> 1.2 | AC19: =Z19+AA19-AB19 -> -7.6145 | AD19: 0 | AE19: =ROUND(AD7*15,0)/10000 -> 0 | AF19: =AC19+AD19-AE19 -> -7.6145 | AG19: 0 | AH19: =ROUND(AG7*15,0)/10000 -> 0 | AI19: =AF19+AG19-AH19 -> -7.6145 | AJ19: =SUM(AG19,AD19,AA19,X19,U19,R19,O19,L19,I19,F19,C19) -> 4.408 | AK19: =SUM(AH19,AE19,AB19,Y19,V19,S19,P19,M19,J19,G19,D19) -> 7.8465 | AL19: =B19+AJ19-AK19 -> -7.6145
A20: मसाला | B20: 1.654 | C20: 0 | D20: =ROUND(C7*3,0)/1000 -> 0.99 | E20: =B20+C20-D20 -> 0.664 | F20: 0 | G20: =ROUND(F7*3,0)/1000 -> 1.209 | H20: =E20+F20-G20 -> -0.545 | I20: 1 | J20: =ROUND(I7*3,0)/1000 -> 2.358 | K20: =H20+I20-J20 -> -1.903 | L20: 1.728 | M20: =ROUND(L7*3,0)/1000 -> 1.728 | N20: =K20+L20-M20 -> -1.903 | O20: 2.016 | P20: =ROUND(O7*3,0)/1000 -> 2.016 | Q20: =N20+O20-P20 -> -1.903 | R20: 1.056 | S20: =ROUND(R7*3,0)/1000 -> 1.056 | T20: =Q20+R20-S20 -> -1.903 | U20: 2.016 | V20: =ROUND(U7*3,0)/1000 -> 2.016 | W20: =T20+U20-V20 -> -1.903 | X20: 0.5 | Y20: 1.92 | Z20: =W20+X20-Y20 -> -3.323 | AA20: 0 | AB20: =ROUND(AA7*3,0)/1000 -> 2.4 | AC20: =Z20+AA20-AB20 -> -5.723 | AD20: 0 | AE20: =ROUND(AD7*3,0)/1000 -> 0 | AF20: =AC20+AD20-AE20 -> -5.723 | AG20: 0 | AH20: =ROUND(AG7*3,0)/1000 -> 0 | AI20: =AF20+AG20-AH20 -> -5.723 | AJ20: =SUM(AG20,AD20,AA20,X20,U20,R20,O20,L20,I20,F20,C20) -> 8.316 | AK20: =SUM(AH20,AE20,AB20,Y20,V20,S20,P20,M20,J20,G20,D20) -> 15.693 | AL20: =B20+AJ20-AK20 -> -5.723
A21: तेल | B21: 0.289 | C21: 0 | D21: =ROUND(C7*4,0)/1000 -> 1.32 | E21: =B21+C21-D21 -> -1.031 | F21: 0 | G21: =ROUND(F7*4,0)/1000 -> 1.612 | H21: =E21+F21-G21 -> -2.643 | I21: 6.37 | J21: =ROUND(I7*4,0)/1000 -> 3.144 | K21: =H21+I21-J21 -> 0.583 | L21: 2.304 | M21: =ROUND(L7*4,0)/1000 -> 2.304 | N21: =K21+L21-M21 -> 0.583 | O21: 2.688 | P21: =ROUND(O7*4,0)/1000 -> 2.688 | Q21: =N21+O21-P21 -> 0.583 | R21: 1.408 | S21: =ROUND(R7*4,0)/1000 -> 1.408 | T21: =Q21+R21-S21 -> 0.583 | U21: 2.688 | V21: =ROUND(U7*4,0)/1000 -> 2.688 | W21: =T21+U21-V21 -> 0.583 | X21: 5.46 | Y21: 2.56 | Z21: =W21+X21-Y21 -> 3.483 | AA21: 0 | AB21: =ROUND(AA7*4,0)/1000 -> 3.2 | AC21: =Z21+AA21-AB21 -> 0.283 | AD21: 0 | AE21: =ROUND(AD7*4,0)/1000 -> 0 | AF21: =AC21+AD21-AE21 -> 0.283 | AG21: 0 | AH21: =ROUND(AG7*4,0)/1000 -> 0 | AI21: =AF21+AG21-AH21 -> 0.283 | AJ21: =SUM(AG21,AD21,AA21,X21,U21,R21,O21,L21,I21,F21,C21) -> 20.918 | AK21: =SUM(AH21,AE21,AB21,Y21,V21,S21,P21,M21,J21,G21,D21) -> 20.924 | AL21: =B21+AJ21-AK21 -> 0.283
A22: मीठ | B22: -8.74 | C22: 0 | D22: =ROUND(C7*2,0)/1000 -> 0.66 | E22: =B22+C22-D22 -> -9.4 | F22: 0 | G22: =ROUND(F7*2,0)/1000 -> 0.806 | H22: =E22+F22-G22 -> -10.206 | I22: 3 | J22: =ROUND(I7*2,0)/1000 -> 1.572 | K22: =H22+I22-J22 -> -8.778 | L22: 1.152 | M22: =ROUND(L7*2,0)/1000 -> 1.152 | N22: =K22+L22-M22 -> -8.778 | O22: 1.344 | P22: =ROUND(O7*2,0)/1000 -> 1.344 | Q22: =N22+O22-P22 -> -8.778 | R22: 0.704 | S22: =ROUND(R7*2,0)/1000 -> 0.704 | T22: =Q22+R22-S22 -> -8.778 | U22: 1.344 | V22: =ROUND(U7*2,0)/1000 -> 1.344 | W22: =T22+U22-V22 -> -8.778 | X22: 3 | Y22: 1.28 | Z22: =W22+X22-Y22 -> -7.058 | AA22: 0 | AB22: =ROUND(AA7*2,0)/1000 -> 1.6 | AC22: =Z22+AA22-AB22 -> -8.658 | AD22: 0 | AE22: =ROUND(AD7*2,0)/1000 -> 0 | AF22: =AC22+AD22-AE22 -> -8.658 | AG22: 0 | AH22: =ROUND(AG7*2,0)/1000 -> 0 | AI22: =AF22+AG22-AH22 -> -8.658 | AJ22: =SUM(AG22,AD22,AA22,X22,U22,R22,O22,L22,I22,F22,C22) -> 10.544 | AK22: =SUM(AH22,AE22,AB22,Y22,V22,S22,P22,M22,J22,G22,D22) -> 10.462 | AL22: =B22+AJ22-AK22 -> -8.658
A23: तिखट | B23: 0 | C23: 0 | D23: 0 | E23: =B23+C23-D23 -> 0 | F23: 0 | G23: 0 | H23: =E23+F23-G23 -> 0 | I23: 0 | J23: 0 | K23: =H23+I23-J23 -> 0 | L23: 0 | M23: 0 | N23: =K23+L23-M23 -> 0 | O23: 0 | P23: 0 | Q23: =N23+O23-P23 -> 0 | R23: 0 | S23: 0 | T23: =Q23+R23-S23 -> 0 | U23: 0 | V23: 0 | W23: =T23+U23-V23 -> 0 | X23: 0 | Y23: 0 | Z23: =W23+X23-Y23 -> 0 | AA23: 0 | AB23: 0 | AC23: =Z23+AA23-AB23 -> 0 | AD23: 0 | AE23: 0 | AF23: =AC23+AD23-AE23 -> 0 | AG23: 0 | AH23: 0 | AI23: =AF23+AG23-AH23 -> 0 | AJ23: =SUM(AG23,AD23,AA23,X23,U23,R23,O23,L23,I23,F23,C23) -> 0 | AK23: =SUM(AH23,AE23,AB23,Y23,V23,S23,P23,M23,J23,G23,D23) -> 0 | AL23: =B23+AJ23-AK23 -> 0

Sheet Sheet1
A1: शालेय पोषण आहार योजना, पंचायत समिती मुरबाड
A2: प्रपत्र ब गोषवारा
L3: माहे : | M3: जून 2017
A4: अ.क्र. | B4: शाळेचे नांव | C4: पटसंख्या | D4: प्रत्यक्ष कामाचे दिवस | E4: IFSC CODE | F4: खाते क्रमांक | G4: बँकेचे नांव | H4: लाभार्थी संख्या | J4: अनुज्ञेय रक्कम | L4: एकूण देय रक्कम (9+10) | M4: शेरा (धान्यादी माल खरेदी दिनांक)
H5: केवळ इंधन भाजीपाला | I5: इंधन भाजीपाला + धान्यादी माल | J5: इंधन भाजीपाला खर्च रु.1.51/- | K5: इंधन भाजीपाला + धान्यादी माल खर्च रु. 2.62/-
A6: 1 | B6: जि. प. प्राथमिक शाळा देवराळवाडी | C6: 31 | D6: 13 | E6: MAHB0000703 | F6: 20187923753 | G6: बँक ऑफ महाराष्ट्र, मुरबाड | H6: =C6*D6 -> 403 | I6: =H6 -> 403 | J6: =ROUND(H6*1.51,0) -> 609 | K6: =ROUND(I6*2.62,0) -> 1056 | L6: =SUM(J6:K6) -> 1665 | M6: दि. 15/06/2017
A7: टिप : सदर नमूना इ. 1 ली ते 5 वी व इ. 6 वी ते 8 वी साठी सारखाच राहील केवळ दर बदल होतील दर दि. 28/08/2017 च्या पत्राप्रमाणे आकारावेत.
A9: शालेय पोषण आहार योजना, पंचायत समिती मुरबाड
A10: प्रपत्र ब गोषवारा
L11: माहे : | M11: जुलै 2017
A12: अ.क्र. | B12: शाळेचे नांव | C12: पटसंख्या | D12: प्रत्यक्ष कामाचे दिवस | E12: IFSC CODE | F12: खाते क्रमांक | G12: बँकेचे नांव | H12: लाभार्थी संख्या | J12: अनुज्ञेय रक्कम | L12: एकूण देय रक्कम (9+10) | M12: शेरा (धान्यादी माल खरेदी दिनांक)
H13: केवळ इंधन भाजीपाला | I13: इंधन भाजीपाला + धान्यादी माल | J13: इंधन भाजीपाला खर्च रु.1.51/- | K13: इंधन भाजीपाला + धान्यादी माल खर्च रु. 2.62/-
A14: 1 | B14: जि. प. प्राथमिक शाळा देवराळवाडी | C14: 32 | D14: 25 | E14: MAHB0000703 | F14: 20187923753 | G14: बँक ऑफ महाराष्ट्र, मुरबाड | H14: 786 | I14: =H14 -> 786 | J14: =ROUND(H14*1.51,0) -> 1187 | K14: =ROUND(I14*2.62,0) -> 2059 | L14: =SUM(J14:K14) -> 3246 | M14: दि. 01/07/2017
A15: टिप : सदर नमूना इ. 1 ली ते 5 वी व इ. 6 वी ते 8 वी साठी सारखाच राहील केवळ दर बदल होतील दर दि. 28/08/2017 च्या पत्राप्रमाणे आकारावेत.
A17: शालेय पोषण आहार योजना, पंचायत समिती मुरबाड
A18: प्रपत्र ब गोषवारा
L19: माहे : | M19: ऑगस्ट 2017
A20: अ.क्र. | B20: शाळेचे नांव | C20: पटसंख्या | D20: प्रत्यक्ष कामाचे दिवस | E20: IFSC CODE | F20: खाते क्रमांक | G20: बँकेचे नांव | H20: लाभार्थी संख्या | J20: अनुज्ञेय रक्कम | L20: एकूण देय रक्कम (9+10) | M20: शेरा (धान्यादी माल खरेदी दिनांक)
H21: केवळ इंधन भाजीपाला | I21: इंधन भाजीपाला + धान्यादी माल | J21: इंधन भाजीपाला खर्च रु.1.51/- | K21: इंधन भाजीपाला + धान्यादी माल खर्च रु. 2.62/-
A22: 1 | B22: जि. प. प्राथमिक शाळा देवराळवाडी | C22: 32 | D22: 18 | E22: MAHB0000703 | F22: 20187923753 | G22: बँक ऑफ महाराष्ट्र, मुरबाड | H22: =C22*D22 -> 576 | I22: =H22 -> 576 | J22: =ROUND(H22*1.51,0) -> 870 | K22: =ROUND(I22*2.62,0) -> 1509 | L22: =SUM(J22:K22) -> 2379 | M22: दि. 01/08/2017
A23: टिप : सदर नमूना इ. 1 ली ते 5 वी व इ. 6 वी ते 8 वी साठी सारखाच राहील केवळ दर बदल होतील दर दि. 28/08/2017 च्या पत्राप्रमाणे आकारावेत.
A25: शालेय पोषण आहार योजना, पंचायत समिती मुरबाड
A26: प्रपत्र ब गोषवारा
L27: माहे : | M27: सप्टेंबर 2017
A28: अ.क्र. | B28: शाळेचे नांव | C28: पटसंख्या | D28: प्रत्यक्ष कामाचे दिवस | E28: IFSC CODE | F28: खाते क्रमांक | G28: बँकेचे नांव | H28: लाभार्थी संख्या | J28: अनुज्ञेय रक्कम | L28: एकूण देय रक्कम (9+10) | M28: शेरा (धान्यादी माल खरेदी दिनांक)
H29: केवळ इंधन भाजीपाला | I29: इंधन भाजीपाला + धान्यादी माल | J29: इंधन भाजीपाला खर्च रु.1.51/- | K29: इंधन भाजीपाला + धान्यादी माल खर्च रु. 2.62/-
A30: 1 | B30: जि. प. प्राथमिक शाळा देवराळवाडी | C30: 32 | D30: 21 | E30: MAHB0000703 | F30: 20187923753 | G30: बँक ऑफ महाराष्ट्र, मुरबाड | H30: =C30*D30 -> 672 | I30: =H30 -> 672 | J30: =ROUND(H30*1.51,0) -> 1015 | K30: =ROUND(I30*2.62,0) -> 1761 | L30: =SUM(J30:K30) -> 2776 | M30: दि. 01/09/2017
A31: टिप : सदर नमूना इ. 1 ली ते 5 वी व इ. 6 वी ते 8 वी साठी सारखाच राहील केवळ दर बदल होतील दर दि. 28/08/2017 च्या पत्राप्रमाणे आकारावेत.
A33: शालेय पोषण आहार योजना, पंचायत समिती मुरबाड
A34: प्रपत्र ब गोषवारा
L35: माहे : | M35: ऑक्टोंबर 2017
A36: अ.क्र. | B36: शाळेचे नांव | C36: पटसंख्या | D36: प्रत्यक्ष कामाचे दिवस | E36: IFSC CODE | F36: खाते क्रमांक | G36: बँकेचे नांव | H36: लाभार्थी संख्या | J36: अनुज्ञेय रक्कम | L36: एकूण देय रक्कम (9+10) | M36: शेरा (धान्यादी माल खरेदी दिनांक)
H37: केवळ इंधन भाजीपाला | I37: इंधन भाजीपाला + धान्यादी माल | J37: इंधन भाजीपाला खर्च रु.1.51/- | K37: इंधन भाजीपाला + धान्यादी माल खर्च रु. 2.62/-
A38: 1 | B38: जि. प. प्राथमिक शाळा देवराळवाडी | C38: 32 | D38: 11 | E38: MAHB0000703 | F38: 20187923753 | G38: बँक ऑफ महाराष्ट्र, मुरबाड | H38: =C38*D38 -> 352 | I38: =H38 -> 352 | J38: =ROUND(H38*1.51,0) -> 532 | K38: =ROUND(I38*2.62,0) -> 922 | L38: =SUM(J38:K38) -> 1454 | M38: दि. 01/09/2017
A39: टिप : सदर नमूना इ. 1 ली ते 5 वी व इ. 6 वी ते 8 वी साठी सारखाच राहील केवळ दर बदल होतील दर दि. 28/08/2017 च्या पत्राप्रमाणे आकारावेत.
A41: शालेय पोषण आहार योजना, पंचायत समिती मुरबाड
A42: प्रपत्र ब गोषवारा
L43: माहे : | M43: नोव्हेंबर 2017
A44: अ.क्र. | B44: शाळेचे नांव | C44: पटसंख्या | D44: प्रत्यक्ष कामाचे दिवस | E44: IFSC CODE | F44: खाते क्रमांक | G44: बँकेचे नांव | H44: लाभार्थी संख्या | J44: अनुज्ञेय रक्कम | L44: एकूण देय रक्कम (9+10) | M44: शेरा (धान्यादी माल खरेदी दिनांक)
H45: केवळ इंधन भाजीपाला | I45: इंधन भाजीपाला + धान्यादी माल | J45: इंधन भाजीपाला खर्च रु.1.51/- | K45: इंधन भाजीपाला + धान्यादी माल खर्च रु. 2.62/-
...

Sheet Sheet2
A1: शालेय पोषण आहार योजना, पंचायत समिती मुरबाड
A2: स्वयंपाकी व मदतनीस मानधन मागणी तक्ता
I3: डिसेंबर 2017
A4: अ.क्र. | B4: शाळेचे नांव | C4: स्वयंपाकी मदतनीस नांव | D4: बँकेचे नांव | E4: शाखेचे नांव | F4: खाते क्रमांक | G4: IFSC CODE | H4: मानधन रक्कम रुपये | I4: शेरा
A5: 1 | B5: जि. प. प्राथमिक शाळा देवराळवाडी | C5: गुलाब देवराम निरगुडा (स्वयंपाकी) | D5: दि ठाणे जिल्हा मध्यवर्ती सहकारी बँक लि. | E5: मुरबाड | F5: 02900300044984 | G5: TDCB0000029 | H5: 1000
A6: 2 | C6: वनिता देवराम निरगुडा (मदतनीस) | D6: दि ठाणे जिल्हा मध्यवर्ती सहकारी बँक लि. | E6: मुरबाड | F6: 02900300052828 | G6: TDCB0000029 | H6: 1000

Sheet 1 to 5 (2)
A1: शालेय पोषण आहार सन 2018-19 इ. 1 ली ते 5 वी
A2: शाळेचे नांव : | C2: रा .जि. प.उच्च प्राथमिक शाळा मेंगाळवाडी | J2: केंद्र : खांडस | O2: तालुका : कर्जत | R2: जिल्हा : रायगड | U2: महिना : | V2: Desember २०१९
A3: दिनांक | B3: वार | C3: वार कोड | D3: आजचा आहार | E3: लाभार्थी ↓ | F3: ताटांची संख्या | G3: तांदूळ | H3: तूरडाळ | I3: मूगडाळ | J3: मसूरडाळ | K3: मटकी | M3: वाटाणा/ हरभरा | N3: हरभरा | O3: मसाल्याचे पदार्थ (ग्रॅममध्ये) | T3: सोयाबीन तेल | U3: मीठ | V3: इंधन खर्च | W3: शेरा
L4: मसुरडाळ | O4: मोहरी | P4: जिरे | Q4: हळद | R4: मिरची पावडर | S4: कांदा लसून मसाला
E5: प्रमाण | G5: 0.1 | H5: 0.02 | I5: 0.02 | J5: 0.02 | K5: 0.02 | L5: 0.02 | M5: 0.02 | N5: 0.02 | O5: 0.00015 | P5: 0.0002 | Q5: 0.00015 | R5: 0.003 | S5: 0.0009 | T5: 0.005 | U5: 0.0007
A6: 1 | B6: 2 | C6: 3 | D6: 4 | E6: 5 | F6: 6 | G6: 7 | H6: 8 | J6: 9 | K6: 10 | M6: 10 | N6: 11 | O6: 12 | P6: 13 | Q6: 14 | R6: 15 | S6: 16 | T6: 17 | U6: 18 | V6: 19 | W6: 20
B7: मागील शिल्लक धान्य/किराणा :- | G7: 160.6 | H7: 2.82 | I7: 8.68 | J7: 0 | K7: 11.76 | L7: 18.54 | M7: 15.14 | N7: -0.78 | O7: 3.224 | P7: 3.011 | Q7: 3.233 | R7: -1.422 | S7: 3.24 | T7: 12.875 | U7: 8.85
B8: प्राप्त धान्य/किराणा :-
B9: एकूण प्राप्त धान्य/किराणा :- | H9: =SUM(H7:H8) -> 2.82 | I9: =SUM(I7:I8) -> 8.68 | J9: =SUM(J7:J8) -> 0 | K9: =SUM(K7:K8) -> 11.76 | L9: =L7+L8 -> 18.54 | M9: =SUM(M7:M8) -> 15.14 | N9: =SUM(N7:N8) -> -0.78 | O9: =SUM(O7:O8) -> 3.224 | P9: =SUM(P7:P8) -> 3.011 | Q9: =SUM(Q7:Q8) -> 3.233 | R9: =SUM(R7:R8) -> -1.422 | S9: =SUM(S7:S8) -> 3.24 | T9: =SUM(T7:T8) -> 12.875 | U9: =SUM(U7:U8) -> 8.85
A10: 1 | B10: =IF(C10=0,"सुट्टी",IF(C10=1,"रविवार",IF(C10=2,"सोमवार",IF(C10=3,"मंगळवार",IF(C10=4,"बुधवार",IF(C10=5,"गुरुवार",IF(C10=6,"शुक्रवार",IF(C10=7,"शनिवार")))))))) -> रविवार | C10: 1 | D10: =IF(C10=0,"",IF(C10=1,"",IF(C10=2,"मुगडाळ खिचडी",IF(C10=3,"वरणभात",IF(C10=4,"उसळभात",IF(C10=5,"खिचडी",IF(C10=6,"आमटीभात",IF(C10=7,"उसळभात")))))))) | E10: 0 | F10: 0 | G10: =E10*0.1 -> 0 | H10: =IF(C10=3,SUM(E10*0.02),IF(C10=5,SUM(E10*0.02),IF(C10=6,SUM(E10*0.02),""))) | I10: =IF(C10=2,SUM(E10*0.02),"") | J10: =IF(C10=2,SUM(E10*0.02),"") | K10: =IF(C10=7,SUM(E10*0.02),"") | M10: =IF(C10=4,SUM(E10*0.02),"") | N10: =IF(C10=4,SUM(E10*0.02),"") | O10: =IF(C10=2,SUM(E10*0.00015),IF(C10=3,SUM(E10*0.00015),IF(C10=4,SUM(E10*0.00015),IF(C10=5,SUM(E10*0.00015),IF(C10=6,SUM(E10*0.00015),IF(C10=7,SUM(E10*0.00015),"")))))) | P10: =IF(C10=2,SUM(E10*0.0002),IF(C10=3,SUM(E10*0.0002),IF(C10=4,SUM(E10*0.0002),IF(C10=5,SUM(E10*0.0002),IF(C10=6,SUM(E10*0.0002),IF(C10=7,SUM(E10*0.0002),"")))))) | Q10: =IF(C10=2,SUM(E10*0.00015),IF(C10=3,SUM(E10*0.00015),IF(C10=4,SUM(E10*0.00015),IF(C10=5,SUM(E10*0.00015),IF(C10=6,SUM(E10*0.00015),IF(C10=7,SUM(E10*0.00015),"")))))) | R10: =IF(C10=2,SUM(E10*0.003),IF(C10=3,SUM(E10*0.003),IF(C10=4,SUM(E10*0.003),IF(C10=5,SUM(E10*0.003),IF(C10=6,SUM(E10*0.003),IF(C10=7,SUM(E10*0.003),"")))))) | S10: =IF(C10=2,SUM(E10*0.0009),IF(C10=3,SUM(E10*0.0009),IF(C10=4,SUM(E10*0.0009),IF(C10=5,SUM(E10*0.0009),IF(C10=6,SUM(E10*0.0009),IF(C10=7,SUM(E10*0.0009),"")))))) | T10: =IF(C10=2,SUM(E10*0.005),IF(C10=3,SUM(E10*0.005),IF(C10=4,SUM(E10*0.005),IF(C10=5,SUM(E10*0.005),IF(C10=6,SUM(E10*0.005),IF(C10=7,SUM(E10*0.005),"")))))) | U10: =IF(C10=2,SUM(E10*0.0007),IF(C10=3,SUM(E10*0.0007),IF(C10=4,SUM(E10*0.0007),IF(C10=5,SUM(E10*0.0007),IF(C10=6,SUM(E10*0.0007),IF(C10=7,SUM(E10*0.0007),"")))))) | V10: =IF(C10=2,SUM(E10*1.51),IF(C10=3,SUM(E10*1.51),IF(C10=4,SUM(E10*1.51),IF(C10=5,SUM(E10*1.51),IF(C10=6,SUM(E10*1.51),IF(C10=7,SUM(E10*1.51),""))))))
A11: 2 | B11: =IF(C11=0,"सुट्टी",IF(C11=1,"रविवार",IF(C11=2,"सोमवार",IF(C11=3,"मंगळवार",IF(C11=4,"बुधवार",IF(C11=5,"गुरुवार",IF(C11=6,"शुक्रवार",IF(C11=7,"शनिवार")))))))) -> सोमवार | C11: 2 | D11: =IF(C11=0,"",IF(C11=1,"",IF(C11=2,"मुगडाळ खिचडी",IF(C11=3,"वरणभात",IF(C11=4,"उसळभात",IF(C11=5,"खिचडी",IF(C11=6,"आमटीभात",IF(C11=7,"उसळभात")))))))) -> मुगडाळ खिचडी | E11: 8 | F11: 8 | G11: =E11*0.1 -> 0.8
A12: 3 | B12: =IF(C12=0,"सुट्टी",IF(C12=1,"रविवार",IF(C12=2,"सोमवार",IF(C12=3,"मंगळवार",IF(C12=4,"बुधवार",IF(C12=5,"गुरुवार",IF(C12=6,"शुक्रवार",IF(C12=7,"शनिवार")))))))) -> मंगळवार | C12: 3 | D12: =IF(C12=0,"",IF(C12=1,"",IF(C12=2,"मुगडाळ खिचडी",IF(C12=3,"वरणभात",IF(C12=4,"उसळभात",IF(C12=5,"खिचडी",IF(C12=6,"आमटीभात",IF(C12=7,"उसळभात")))))))) -> वरणभात | E12: 8 | F12: 8 | G12: =E12*0.1 -> 0.8
A13: 4 | B13: =IF(C13=0,"सुट्टी",IF(C13=1,"रविवार",IF(C13=2,"सोमवार",IF(C13=3,"मंगळवार",IF(C13=4,"बुधवार",IF(C13=5,"गुरुवार",IF(C13=6,"शुक्रवार",IF(C13=7,"शनिवार")))))))) -> बुधवार | C13: 4 | D13: =IF(C13=0,"",IF(C13=1,"",IF(C13=2,"मुगडाळ खिचडी",IF(C13=3,"वरणभात",IF(C13=4,"उसळभात",IF(C13=5,"खिचडी",IF(C13=6,"आमटीभात",IF(C13=7,"उसळभात")))))))) -> उसळभात | E13: 7 | F13: 7 | G13: =E13*0.1 -> 0.7
A14: 5 | B14: =IF(C14=0,"सुट्टी",IF(C14=1,"रविवार",IF(C14=2,"सोमवार",IF(C14=3,"मंगळवार",IF(C14=4,"बुधवार",IF(C14=5,"गुरुवार",IF(C14=6,"शुक्रवार",IF(C14=7,"शनिवार")))))))) -> गुरुवार | C14: 5 | D14: =IF(C14=0,"",IF(C14=1,"",IF(C14=2,"मुगडाळ खिचडी",IF(C14=3,"वरणभात",IF(C14=4,"उसळभात",IF(C14=5,"खिचडी",IF(C14=6,"आमटीभात",IF(C14=7,"उसळभात")))))))) -> खिचडी | E14: 7 | F14: 7 | G14: =E14*0.1 -> 0.7
A15: 6 | B15: =IF(C15=0,"सुट्टी",IF(C15=1,"रविवार",IF(C15=2,"सोमवार",IF(C15=3,"मंगळवार",IF(C15=4,"बुधवार",IF(C15=5,"गुरुवार",IF(C15=6,"शुक्रवार",IF(C15=7,"शनिवार")))))))) -> शुक्रवार | C15: 6 | D15: =IF(C15=0,"",IF(C15=1,"",IF(C15=2,"मुगडाळ खिचडी",IF(C15=3,"वरणभात",IF(C15=4,"उसळभात",IF(C15=5,"खिचडी",IF(C15=6,"आमटीभात",IF(C15=7,"उसळभात")))))))) -> आमटीभात | E15: 7 | F15: 7 | G15: =E15*0.1 -> 0.7
A16: 7 | B16: =IF(C16=0,"सुट्टी",IF(C16=1,"रविवार",IF(C16=2,"सोमवार",IF(C16=3,"मंगळवार",IF(C16=4,"बुधवार",IF(C16=5,"गुरुवार",IF(C16=6,"शुक्रवार",IF(C16=7,"शनिवार")))))))) -> शनिवार | C16: 7 | D16: =IF(C16=0,"",IF(C16=1,"",IF(C16=2,"मुगडाळ खिचडी",IF(C16=3,"वरणभात",IF(C16=4,"उसळभात",IF(C16=5,"खिचडी",IF(C16=6,"आमटीभात",IF(C16=7,"उसळभात")))))))) -> उसळभात | E16: 7 | F16: 7 | G16: =E16*0.1 -> 0.7 | I16: 0.18 | K16: 0.16 | L16: 0.14
A17: 8 | B17: =IF(C17=0,"सुट्टी",IF(C17=1,"रविवार",IF(C17=2,"सोमवार",IF(C17=3,"मंगळवार",IF(C17=4,"बुधवार",IF(C17=5,"गुरुवार",IF(C17=6,"शुक्रवार",IF(C17=7,"शनिवार")))))))) -> रविवार | C17: 1 | D17: =IF(C17=0,"",IF(C17=1,"",IF(C17=2,"मुगडाळ खिचडी",IF(C17=3,"वरणभात",IF(C17=4,"उसळभात",IF(C17=5,"खिचडी",IF(C17=6,"आमटीभात",IF(C17=7,"उसळभात")))))))) | E17: 0 | F17: 0 | G17: =E17*0.1 -> 0 | H17: 0.1 | K17: 0.18 | L17: 0.16
A18: 9 | B18: =IF(C18=0,"सुट्टी",IF(C18=1,"रविवार",IF(C18=2,"सोमवार",IF(C18=3,"मंगळवार",IF(C18=4,"बुधवार",IF(C18=5,"गुरुवार",IF(C18=6,"शुक्रवार",IF(C18=7,"शनिवार")))))))) -> सोमवार | C18: 2 | D18: =IF(C18=0,"",IF(C18=1,"",IF(C18=2,"मुगडाळ खिचडी",IF(C18=3,"वरणभात",IF(C18=4,"उसळभात",IF(C18=5,"खिचडी",IF(C18=6,"आमटीभात",IF(C18=7,"उसळभात")))))))) -> मुगडाळ खिचडी | E18: 8 | F18: 8 | G18: =E18*0.1 -> 0.8 | H18: 0.16 | K18: 0.18 | L18: 0.18
A19: 10 | B19: =IF(C19=0,"सुट्टी",IF(C19=1,"रविवार",IF(C19=2,"सोमवार",IF(C19=3,"मंगळवार",IF(C19=4,"बुधवार",IF(C19=5,"गुरुवार",IF(C19=6,"शुक्रवार",IF(C19=7,"शनिवार")))))))) -> मंगळवार | C19: 3 | D19: =IF(C19=0,"",IF(C19=1,"",IF(C19=2,"मुगडाळ खिचडी",IF(C19=3,"वरणभात",IF(C19=4,"उसळभात",IF(C19=5,"खिचडी",IF(C19=6,"आमटीभात",IF(C19=7,"उसळभात")))))))) -> वरणभात | E19: 8 | F19: 8 | G19: =E19*0.1 -> 0.8 | H19: 0.18 | K19: 0.18 | L19: 0.18
A20: 11 | B20: =IF(C20=0,"सुट्टी",IF(C20=1,"रविवार",IF(C20=2,"सोमवार",IF(C20=3,"मंगळवार",IF(C20=4,"बुधवार",IF(C20=5,"गुरुवार",IF(C20=6,"शुक्रवार",IF(C20=7,"शनिवार")))))))) -> बुधवार | C20: 4 | D20: =IF(C20=0,"",IF(C20=1,"",IF(C20=2,"मुगडाळ खिचडी",IF(C20=3,"वरणभात",IF(C20=4,"उसळभात",IF(C20=5,"खिचडी",IF(C20=6,"आमटीभात",IF(C20=7,"उसळभात")))))))) -> उसळभात | E20: 9 | F20: 9 | G20: =E20*0.1 -> 0.9 | H20: 0.18
A21: 12 | B21: =IF(C21=0,"सुट्टी",IF(C21=1,"रविवार",IF(C21=2,"सोमवार",IF(C21=3,"मंगळवार",IF(C21=4,"बुधवार",IF(C21=5,"गुरुवार",IF(C21=6,"शुक्रवार",IF(C21=7,"शनिवार")))))))) -> गुरुवार | C21: 5 | D21: =IF(C21=0,"",IF(C21=1,"",IF(C21=2,"मुगडाळ खिचडी",IF(C21=3,"वरणभात",IF(C21=4,"उसळभात",IF(C21=5,"खिचडी",IF(C21=6,"आमटीभात",IF(C21=7,"उसळभात")))))))) -> खिचडी | E21: 9 | F21: 9 | G21: =E21*0.1 -> 0.9
A22: 13 | B22: =IF(C22=0,"सुट्टी",IF(C22=1,"रविवार",IF(C22=2,"सोमवार",IF(C22=3,"मंगळवार",IF(C22=4,"बुधवार",IF(C22=5,"गुरुवार",IF(C22=6,"शुक्रवार",IF(C22=7,"शनिवार")))))))) -> शुक्रवार | C22: 6 | D22: =IF(C22=0,"",IF(C22=1,"",IF(C22=2,"मुगडाळ खिचडी",IF(C22=3,"वरणभात",IF(C22=4,"उसळभात",IF(C22=5,"खिचडी",IF(C22=6,"आमटीभात",IF(C22=7,"उसळभात")))))))) -> आमटीभात | E22: 0 | F22: 0 | G22: =E22*0.1 -> 0 | I22: 0.18
A23: 14 | B23: =IF(C23=0,"सुट्टी",IF(C23=1,"रविवार",IF(C23=2,"सोमवार",IF(C23=3,"मंगळवार",IF(C23=4,"बुधवार",IF(C23=5,"गुरुवार",IF(C23=6,"शुक्रवार",IF(C23=7,"शनिवार")))))))) -> शनिवार | C23: 7 | D23: =IF(C23=0,"",IF(C23=1,"",IF(C23=2,"मुगडाळ खिचडी",IF(C23=3,"वरणभात",IF(C23=4,"उसळभात",IF(C23=5,"खिचडी",IF(C23=6,"आमटीभात",IF(C23=7,"उसळभात")))))))) -> उसळभात | E23: 9 | F23: 9 | G23: =E23*0.1 -> 0.9
A24: 15 | B24: =IF(C24=0,"सुट्टी",IF(C24=1,"रविवार",IF(C24=2,"सोमवार",IF(C24=3,"मंगळवार",IF(C24=4,"बुधवार",IF(C24=5,"गुरुवार",IF(C24=6,"शुक्रवार",IF(C24=7,"शनिवार")))))))) -> रविवार | C24: 1 | D24: =IF(C24=0,"",IF(C24=1,"",IF(C24=2,"मुगडाळ खिचडी",IF(C24=3,"वरणभात",IF(C24=4,"उसळभात",IF(C24=5,"खिचडी",IF(C24=6,"आमटीभात",IF(C24=7,"उसळभात")))))))) | E24: 0 | F24: 0 | G24: =E24*0.1 -> 0
A25: 16 | B25: =IF(C25=0,"सुट्टी",IF(C25=1,"रविवार",IF(C25=2,"सोमवार",IF(C25=3,"मंगळवार",IF(C25=4,"बुधवार",IF(C25=5,"गुरुवार",IF(C25=6,"शुक्रवार",IF(C25=7,"शनिवार")))))))) -> सोमवार | C25: 2 | D25: =IF(C25=0,"",IF(C25=1,"",IF(C25=2,"मुगडाळ खिचडी",IF(C25=3,"वरणभात",IF(C25=4,"उसळभात",IF(C25=5,"खिचडी",IF(C25=6,"आमटीभात",IF(C25=7,"उसळभात")))))))) -> मुगडाळ खिचडी | E25: 9 | F25: 9 | G25: =E25*0.1 -> 0.9
A26: 17 | B26: =IF(C26=0,"सुट्टी",IF(C26=1,"रविवार",IF(C26=2,"सोमवार",IF(C26=3,"मंगळवार",IF(C26=4,"बुधवार",IF(C26=5,"गुरुवार",IF(C26=6,"शुक्रवार",IF(C26=7,"शनिवार")))))))) -> मंगळवार | C26: 3 | D26: =IF(C26=0,"",IF(C26=1,"",IF(C26=2,"मुगडाळ खिचडी",IF(C26=3,"वरणभात",IF(C26=4,"उसळभात",IF(C26=5,"खिचडी",IF(C26=6,"आमटीभात",IF(C26=7,"उसळभात")))))))) -> वरणभात | E26: 9 | F26: 9 | G26: =E26*0.1 -> 0.9
A27: 18 | B27: =IF(C27=0,"सुट्टी",IF(C27=1,"रविवार",IF(C27=2,"सोमवार",IF(C27=3,"मंगळवार",IF(C27=4,"बुधवार",IF(C27=5,"गुरुवार",IF(C27=6,"शुक्रवार",IF(C27=7,"शनिवार")))))))) -> बुधवार | C27: 4 | D27: =IF(C27=0,"",IF(C27=1,"",IF(C27=2,"मुगडाळ खिचडी",IF(C27=3,"वरणभात",IF(C27=4,"उसळभात",IF(C27=5,"खिचडी",IF(C27=6,"आमटीभात",IF(C27=7,"उसळभात")))))))) -> उसळभात | E27: 9 | F27: 9 | G27: =E27*0.1 -> 0.9
A28: 19 | B28: =IF(C28=0,"सुट्टी",IF(C28=1,"रविवार",IF(C28=2,"सोमवार",IF(C28=3,"मंगळवार",IF(C28=4,"बुधवार",IF(C28=5,"गुरुवार",IF(C28=6,"शुक्रवार",IF(C28=7,"शनिवार")))))))) -> गुरुवार | C28: 5 | D28: =IF(C28=0,"",IF(C28=1,"",IF(C28=2,"मुगडाळ खिचडी",IF(C28=3,"वरणभात",IF(C28=4,"उसळभात",IF(C28=5,"खिचडी",IF(C28=6,"आमटीभात",IF(C28=7,"उसळभात")))))))) -> खिचडी | E28: 8 | F28: 8 | G28: =E28*0.1 -> 0.8
A29: 20 | B29: =IF(C29=0,"सुट्टी",IF(C29=1,"रविवार",IF(C29=2,"सोमवार",IF(C29=3,"मंगळवार",IF(C29=4,"बुधवार",IF(C29=5,"गुरुवार",IF(C29=6,"शुक्रवार",IF(C29=7,"शनिवार")))))))) -> शुक्रवार | C29: 6 | D29: =IF(C29=0,"",IF(C29=1,"",IF(C29=2,"मुगडाळ खिचडी",IF(C29=3,"वरणभात",IF(C29=4,"उसळभात",IF(C29=5,"खिचडी",IF(C29=6,"आमटीभात",IF(C29=7,"उसळभात")))))))) -> आमटीभात | E29: 8 | F29: 8 | G29: =E29*0.1 -> 0.8 | I29: 0.16
A30: 21 | B30: =IF(C30=0,"सुट्टी",IF(C30=1,"रविवार",IF(C30=2,"सोमवार",IF(C30=3,"मंगळवार",IF(C30=4,"बुधवार",IF(C30=5,"गुरुवार",IF(C30=6,"शुक्रवार",IF(C30=7,"शनिवार")))))))) -> शनिवार | C30: 7 | D30: =IF(C30=0,"",IF(C30=1,"",IF(C30=2,"मुगडाळ खिचडी",IF(C30=3,"वरणभात",IF(C30=4,"उसळभात",IF(C30=5,"खिचडी",IF(C30=6,"आमटीभात",IF(C30=7,"उसळभात")))))))) -> उसळभात | E30: 7 | F30: 7 | G30: =E30*0.1 -> 0.7
A31: 22 | B31: =IF(C31=0,"सुट्टी",IF(C31=1,"रविवार",IF(C31=2,"सोमवार",IF(C31=3,"मंगळवार",IF(C31=4,"बुधवार",IF(C31=5,"गुरुवार",IF(C31=6,"शुक्रवार",IF(C31=7,"शनिवार")))))))) -> रविवार | C31: 1 | D31: =IF(C31=0,"",IF(C31=1,"",IF(C31=2,"मुगडाळ खिचडी",IF(C31=3,"वरणभात",IF(C31=4,"उसळभात",IF(C31=5,"खिचडी",IF(C31=6,"आमटीभात",IF(C31=7,"उसळभात")))))))) | E31: 0 | F31: 0 | G31: =E31*0.1 -> 0
A32: 23 | B32: =IF(C32=0,"सुट्टी",IF(C32=1,"रविवार",IF(C32=2,"सोमवार",IF(C32=3,"मंगळवार",IF(C32=4,"बुधवार",IF(C32=5,"गुरुवार",IF(C32=6,"शुक्रवार",IF(C32=7,"शनिवार")))))))) -> सोमवार | C32: 2 | D32: =IF(C32=0,"",IF(C32=1,"",IF(C32=2,"मुगडाळ खिचडी",IF(C32=3,"वरणभात",IF(C32=4,"उसळभात",IF(C32=5,"खिचडी",IF(C32=6,"आमटीभात",IF(C32=7,"उसळभात")))))))) -> मुगडाळ खिचडी | E32: 9 | F32: 9 | G32: =E32*0.1 -> 0.9
A33: 24 | B33: =IF(C33=0,"सुट्टी",IF(C33=1,"रविवार",IF(C33=2,"सोमवार",IF(C33=3,"मंगळवार",IF(C33=4,"बुधवार",IF(C33=5,"गुरुवार",IF(C33=6,"शुक्रवार",IF(C33=7,"शनिवार")))))))) -> मंगळवार | C33: 3 | D33: =IF(C33=0,"",IF(C33=1,"",IF(C33=2,"मुगडाळ खिचडी",IF(C33=3,"वरणभात",IF(C33=4,"उसळभात",IF(C33=5,"खिचडी",IF(C33=6,"आमटीभात",IF(C33=7,"उसळभात")))))))) -> वरणभात | E33: 8 | F33: 8 | G33: =E33*0.1 -> 0.8
A34: 25 | B34: =IF(C34=0,"सुट्टी",IF(C34=1,"रविवार",IF(C34=2,"सोमवार",IF(C34=3,"मंगळवार",IF(C34=4,"बुधवार",IF(C34=5,"गुरुवार",IF(C34=6,"शुक्रवार",IF(C34=7,"शनिवार")))))))) -> सुट्टी | C34: 0 | D34: =IF(C34=0,"",IF(C34=1,"",IF(C34=2,"मुगडाळ खिचडी",IF(C34=3,"वरणभात",IF(C34=4,"उसळभात",IF(C34=5,"खिचडी",IF(C34=6,"आमटीभात",IF(C34=7,"उसळभात")))))))) | E34: 0 | F34: 0 | G34: =E34*0.1 -> 0
A35: 26 | B35: =IF(C35=0,"सुट्टी",IF(C35=1,"रविवार",IF(C35=2,"सोमवार",IF(C35=3,"मंगळवार",IF(C35=4,"बुधवार",IF(C35=5,"गुरुवार",IF(C35=6,"शुक्रवार",IF(C35=7,"शनिवार")))))))) -> गुरुवार | C35: 5 | D35: =IF(C35=0,"",IF(C35=1,"",IF(C35=2,"मुगडाळ खिचडी",IF(C35=3,"वरणभात",IF(C35=4,"उसळभात",IF(C35=5,"खिचडी",IF(C35=6,"आमटीभात",IF(C35=7,"उसळभात")))))))) -> खिचडी | E35: 7 | F35: 7 | G35: =E35*0.1 -> 0.7
A36: 27 | B36: =IF(C36=0,"सुट्टी",IF(C36=1,"रविवार",IF(C36=2,"सोमवार",IF(C36=3,"मंगळवार",IF(C36=4,"बुधवार",IF(C36=5,"गुरुवार",IF(C36=6,"शुक्रवार",IF(C36=7,"शनिवार")))))))) -> शुक्रवार | C36: 6 | D36: =IF(C36=0,"",IF(C36=1,"",IF(C36=2,"मुगडाळ खिचडी",IF(C36=3,"वरणभात",IF(C36=4,"उसळभात",IF(C36=5,"खिचडी",IF(C36=6,"आमटीभात",IF(C36=7,"उसळभात")))))))) -> आमटीभात | E36: 8 | F36: 8 | G36: =E36*0.1 -> 0.8 | I36: 0.16
A37: 28 | B37: =IF(C37=0,"सुट्टी",IF(C37=1,"रविवार",IF(C37=2,"सोमवार",IF(C37=3,"मंगळवार",IF(C37=4,"बुधवार",IF(C37=5,"गुरुवार",IF(C37=6,"शुक्रवार",IF(C37=7,"शनिवार")))))))) -> शनिवार | C37: 7 | D37: =IF(C37=0,"",IF(C37=1,"",IF(C37=2,"मुगडाळ खिचडी",IF(C37=3,"वरणभात",IF(C37=4,"उसळभात",IF(C37=5,"खिचडी",IF(C37=6,"आमटीभात",IF(C37=7,"उसळभात")))))))) -> उसळभात | E37: 6 | F37: 6 | G37: =E37*0.1 -> 0.6
A38: 29 | B38: =IF(C38=0,"सुट्टी",IF(C38=1,"रविवार",IF(C38=2,"सोमवार",IF(C38=3,"मंगळवार",IF(C38=4,"बुधवार",IF(C38=5,"गुरुवार",IF(C38=6,"शुक्रवार",IF(C38=7,"शनिवार")))))))) -> सुट्टी | C38: 0 | D38: =IF(C38=0,"",IF(C38=1,"",IF(C38=2,"मुगडाळ खिचडी",IF(C38=3,"वरणभात",IF(C38=4,"उसळभात",IF(C38=5,"खिचडी",IF(C38=6,"आमटीभात",IF(C38=7,"उसळभात")))))))) | E38: 0 | F38: 0 | G38: =E38*0.1 -> 0
A39: 30 | B39: =IF(C39=0,"सुट्टी",IF(C39=1,"रविवार",IF(C39=2,"सोमवार",IF(C39=3,"मंगळवार",IF(C39=4,"बुधवार",IF(C39=5,"गुरुवार",IF(C39=6,"शुक्रवार",IF(C39=7,"शनिवार")))))))) -> सोमवार | C39: 2 | D39: =IF(C39=0,"",IF(C39=1,"",IF(C39=2,"मुगडाळ खिचडी",IF(C39=3,"वरणभात",IF(C39=4,"उसळभात",IF(C39=5,"खिचडी",IF(C39=6,"आमटीभात",IF(C39=7,"उसळभात")))))))) -> मुगडाळ खिचडी | E39: 7 | F39: 7 | G39: =E39*0.1 -> 0.7
A40: 31 | B40: =IF(C40=0,"सुट्टी",IF(C40=1,"रविवार",IF(C40=2,"सोमवार",IF(C40=3,"मंगळवार",IF(C40=4,"बुधवार",IF(C40=5,"गुरुवार",IF(C40=6,"शुक्रवार",IF(C40=7,"शनिवार")))))))) -> मंगळवार | C40: 3 | D40: =IF(C40=0,"",IF(C40=1,"",IF(C40=2,"मुगडाळ खिचडी",IF(C40=3,"वरणभात",IF(C40=4,"उसळभात",IF(C40=5,"खिचडी",IF(C40=6,"आमटीभात",IF(C40=7,"उसळभात")))))))) -> वरणभात | E40: 8 | F40: 8 | G40: =E40*0.1 -> 0.8 | O40: 0.0255 | P40: 0.034 | Q40: 0.026
...

Sheet Sheet4
A1: शालेय पोषण आहार योजना - प्रपत्र ब (इ. 1 ते 5)
A2: शाळेने केंद्रप्रमुखांना दरमहा 1 तारखेपर्यंत द्यायचा अहवाल (2 प्रतीत)
A3: शाळेचे नांव : रा.जि.प. प्राथमिक शाळा मेंगाळवाडी, केंद्र :खांडस. ता.कर्जत जि. रायगड
C4: पटसंख्या | F4: 9 | G4: इ. 1 ते 5
C5: महिन्यातील एकूण उपस्थित विद्यार्थी | I5: ='1 to 5 (2)'!E45 -> 190
C6: तांदूळ प्राप्त दिनांक व पावती क्रमांक | G6: एकूण कार्यदिवस | I6: ='1 to 5 (2)'!O45 -> 20
A7: महिना : | B7: नोव्हेंबर २०१९ | G7: अन्न शिजवून दिलेले दिवस | I7: =I6 -> 20
A9: अ.क्र. | B9: वस्तूचे नांव | C9: मागील शिल्लक (कि.ग्रॅ.) | D9: चालू महिन्यात प्राप्त (कि.ग्रॅ.) | E9: एकूण प्राप्त (3+4) (कि.ग्रॅ.) | F9: अन्न शिजवण्यासाठी वापलेल्या वस्तू (कि.ग्रॅ.) | G9: शिल्लक वस्तू (5-6) (कि.ग्रॅ.) | H9: पुढील महिन्यासाठी मागणी (कि.ग्रॅ.) | I9: शेरा
A10: 1 | B10: 2 | C10: 3 | D10: 4 | E10: 5 | F10: 6 | G10: 7 | H10: 8 | I10: 9
A11: 1 | B11: तांदूळ | C11: ='1 to 5 (2)'!G7 -> 160.6 | D11: ='1 to 5 (2)'!G8 -> 0 | E11: =SUM(C11:D11) -> 160.6 | G11: =E11-F11 -> 160.6 | K11: 0.1 | L11: =K11*39*45 -> 175.5 | M11: =L11-G11 -> 14.9
A12: 2 | B12: तूरडाळ | C12: ='1 to 5 (2)'!H7 -> 2.82 | D12: ='1 to 5 (2)'!H8 -> 0 | E12: =SUM(C12:D12) -> 2.82 | F12: ='1 to 5 (2)'!H41 -> 0.62 | G12: =E12-F12 -> 2.2 | K12: 0.02 | L12: =K12*39*18 -> 14.04 | M12: =L12-G12 -> 11.84
A13: 3 | B13: मूगडाळ | C13: ='1 to 5 (2)'!I7 -> 8.68 | D13: 0 | E13: =SUM(C13:D13) -> 8.68 | F13: ='1 to 5 (2)'!I41 -> 0.68 | G13: =E13-F13 -> 8 | K13: 0.02 | L13: =K13*39*6 -> 4.68 | M13: =L13-G13 -> -3.32 | N13: =SUM(#REF!) -> #REF!
A14: 4 | B14: मसूरडाळ | C14: 19.2 | D14: 0 | E14: 19.2 | F14: 0.66 | G14: 18.54 | K14: 0.02 | L14: =K14*39*6 -> 4.68 | M14: =L14-G14 -> -13.86 | N14: =#REF!-N13 -> #REF!
A15: 5 | B15: मटकी | C15: ='1 to 5 (2)'!K7 -> 11.76 | D15: ='1 to 5 (2)'!K8 -> 0 | E15: =SUM(C15:D15) -> 11.76 | F15: ='1 to 5 (2)'!K41 -> 0.7 | G15: =E15-F15 -> 11.06 | K15: 0.02 | L15: =K15*39*6 -> 4.68 | M15: =L15-G15 -> -6.38
A16: 6 | B16: हरभरा | K16: 0.02 | L16: =K16*39*6 -> 4.68 | M16: =L16-G16 -> 4.68
A17: 7 | K17: 0.02 | L17: =K17*39*6 -> 4.68 | M17: =L17-G17 -> 4.68
A18: 8 | B18: मोहरी | C18: ='1 to 5 (2)'!O7 -> 3.224 | D18: ='1 to 5 (2)'!O8 -> 0 | E18: =SUM(C18:D18) -> 3.224 | F18: ='1 to 5 (2)'!O41 -> 0.0255 | G18: =E18-F18 -> 3.1985 | K18: 0.00015 | L18: =K18*39*45 -> 0.26325 | M18: =L18-G18 -> -2.93525
A19: 9 | B19: जिरे | C19: ='1 to 5 (2)'!P7 -> 3.011 | D19: ='1 to 5 (2)'!P8 -> 0 | E19: =SUM(C19:D19) -> 3.011 | F19: ='1 to 5 (2)'!P41 -> 0.034 | G19: =E19-F19 -> 2.977 | K19: 0.0002 | L19: =K19*39*45 -> 0.351 | M19: =L19-G19 -> -2.626
A20: 10 | B20: हळद | C20: ='1 to 5 (2)'!Q7 -> 3.233 | D20: ='1 to 5 (2)'!Q8 -> 0 | E20: =SUM(C20:D20) -> 3.233 | F20: ='1 to 5 (2)'!Q41 -> 0.026 | G20: =E20-F20 -> 3.207 | K20: 0.00015 | L20: =K20*39*45 -> 0.26325 | M20: =L20-G20 -> -2.94375
A21: 11 | B21: मसाला | C21: ='1 to 5 (2)'!S7 -> 3.24 | D21: ='1 to 5 (2)'!S8 -> 0 | E21: =SUM(C21:D21) -> 3.24 | F21: ='1 to 5 (2)'!S41 -> 0 | G21: =E21-F21 -> 3.24 | K21: 0.0009 | L21: =K21*39*45 -> 1.5795 | M21: =L21-G21 -> -1.6605
A22: 12 | B22: सोयाबीन तेल | C22: ='1 to 5 (2)'!T7 -> 12.875 | D22: ='1 to 5 (2)'!T8 -> 0 | E22: =SUM(C22:D22) -> 12.875 | F22: ='1 to 5 (2)'!T41 -> 0 | G22: =E22-F22 -> 12.875 | K22: 0.005 | L22: =K22*39*45 -> 8.775 | M22: =L22-G22 -> -4.1
A23: 13 | B23: मीठ | C23: ='1 to 5 (2)'!U7 -> 8.85 | D23: ='1 to 5 (2)'!U8 -> 0 | E23: =SUM(C23:D23) -> 8.85 | F23: ='1 to 5 (2)'!U41 -> 0 | G23: =E23-F23 -> 8.85 | K23: 0.007 | L23: =K23*39*45 -> 12.285 | M23: =L23-G23 -> 3.435
A24: 14 | B24: मिरची पावडर | C24: 0 | D24: 0 | E24: =SUM(C24:D24) -> 0 | F24: 0 | G24: =E24-F24 -> 0 | K24: 0.0009 | L24: =K24*39*45 -> 1.5795 | M24: =L24-G24 -> 1.5795
A25: * मागणी नोंदवताना शाळेकडे वीस दिवसांचा साठा शिल्लक राहिल याची दक्षता घेऊन मागणी नोंदवावी. आवश्यकतेपेक्षा जास्त साठा करुन धान्य खराब होणार नाही याची दक्षता घ्यावी.
A26: 1) महिन्यातील एकूण ताटांची संख्या : 190
A27: 2) इंधन व भाजीपाल्यासाठी खर्च केलेले अनुदान रु. =305/- (ताटांची संख्या 190 X दर 1.61/-) (शासनस्तरावरुन निश्चित केल्यानुसार)
A28: 3) स्वयंपाकी तथा मदतनीस मानधन रु.1500 /- (रु. 1500 X नेमलेले स्वयंपाकी तथा मदतनीस संख्या)
A29: प्रमाणित करण्यात येते की, वर नमूद केलेले माहिती दैनंदिन नोंदवहीवरुन घेतलेली आहे. ती तपासली आहे व बरोबर आहे.
D32: मुख्याध्यापक/सचिव | H32: केंद्रप्रमुख
A33: दिनांक : | D33: शालेय व्यवस्थापन समिती मेंगाळवाडी | H33: केंद्र : खांडस

Sheet Sheet3
B3: सोमवार | C3: खिचडी | D3: मुगडाळ
B4: मंगळवार | C4: वरणभात | D4: तुरडाळ
B5: बुधवार | C5: उसळभात | D5: हरभरा
B6: गुरुवार | C6: खिचडी | D6: तुरडाळ
B7: शुक्रवार | C7: आमटीभात | D7: तुरडाळ
B8: शनिवार | C8: उसळभात | D8: मटकी
